Workbook

Sheet RESUMO
B2: ABSENTEÍSMO JUNHO - 2026 | EXPEDIÇÃO
B6: Mês | C6: P | D6: BH | E6: FN | F6: FJ | G6: A | H6: T | I6: S | J6: F | K6: Total
B7: JANEIRO | K7: =SUM(C7:J7) -> 0
B8: FEVEREIRO | K8: =SUM(C8:J8) -> 0
B9: MARÇO | K9: =SUM(C9:J9) -> 0
B10: ABRIL | K10: =SUM(C10:J10) -> 0
B11: MAIO | K11: =SUM(C11:J11) -> 0
B12: JUNHO | C12: =JUNHO!F119 -> 2090 | D12: =JUNHO!G119 -> 0 | E12: =JUNHO!H119 -> 24 | F12: =JUNHO!I119 -> 69 | G12: =JUNHO!J119 -> 20 | H12: =JUNHO!K119 -> 0 | I12: =JUNHO!L119 -> 2 | J12: =JUNHO!M119 -> 7 | K12: =SUM(C12:J12) -> 2212
B13: JULHO | C13: =JULHO!F119 -> 219 | D13: =JULHO!G119 -> 0 | E13: =JULHO!H119 -> 1 | F13: =JULHO!I119 -> 6 | G13: =JULHO!J119 -> 3 | H13: =JULHO!K119 -> 1 | I13: =JULHO!L119 -> 2 | J13: =JULHO!M119 -> 1 | K13: =SUM(C13:J13) -> 233
B14: AGOSTO | K14: =SUM(C14:J14) -> 0
B15: SETEMBRO | K15: =SUM(C15:J15) -> 0
B16: OUTUBRO | K16: =SUM(C16:J16) -> 0
B17: NOVEMBRO | K17: =SUM(C17:J17) -> 0
B18: DEZEMBRO | K18: =SUM(C18:J18) -> 0
B19: Total | C19: =SUM(C7:C18) -> 2309 | D19: =SUM(D7:D18) -> 0 | E19: =SUM(E7:E18) -> 25 | F19: =SUM(F7:F18) -> 75 | G19: =SUM(G7:G18) -> 23 | H19: =SUM(H7:H18) -> 1 | I19: =SUM(I7:I18) -> 4 | J19: =SUM(J7:J18) -> 8 | K19: =SUM(K7:K18) -> 2445

Sheet JUNHO
B2: ABSENTEÍSMO EXPEDIÇÃO - JUNHO 2026
O4: SEG | P4: TER | Q4: QUA | R4: QUI | S4: SEX | T4: SÁB | U4: DOM | V4: SEG | W4: TER | X4: QUA | Y4: QUI | Z4: SEX | AA4: SÁB | AB4: DOM | AC4: SEG | AD4: TER | AE4: QUA | AF4: QUI | AG4: SEX | AH4: SÁB | AI4: DOM | AJ4: SEG | AK4: TER | AL4: QUA | AM4: QUI | AN4: SEX | AO4: SÁB | AP4: DOM | AQ4: SEG | AR4: TER
B5: TURNO | C5: NOME COMPLETO | D5: FUNÇÃO | F5: P | G5: BH | H5: FN | I5: FJ | J5: A | K5: T | L5: S | M5: F | O5: 46174 | P5: 46175 | Q5: 46176 | R5: 46177 | S5: 46178 | T5: 46179 | U5: 46180 | V5: 46181 | W5: 46182 | X5: 46183 | Y5: 46184 | Z5: 46185 | AA5: 46186 | AB5: 46187 | AC5: 46188 | AD5: 46189 | AE5: 46190 | AF5: 46191 | AG5: 46192 | AH5: 46193 | AI5: 46194 | AJ5: 46195 | AK5: 46196 | AL5: 46197 | AM5: 46198 | AN5: 46199 | AO5: 46200 | AP5: 46201 | AQ5: 46202 | AR5: 46203
B6: 1º | C6: CICERO ROBERTO DA SILVA | D6: OPERADOR GLP | F6: =COUNTIF(O6:AR6,$F$5) -> 20 | G6: =COUNTIF(O6:AR6,$G$5) -> 0 | H6: =COUNTIF(O6:AR6,$H$5) -> 0 | I6: =COUNTIF(O6:AR6,$I$5) -> 0 | J6: =COUNTIF(O6:AR6,$J$5) -> 0 | K6: =COUNTIF(O6:AR6,$K$5) -> 0 | L6: =COUNTIF(O6:AR6,$L$5) -> 0 | M6: =COUNTIF(O6:AR6,$M$5) -> 0 | O6: P | P6: P | Q6: P | V6: P | W6: P | X6: P | Y6: P | Z6: P | AC6: P | AD6: P | AE6: P | AF6: P | AG6: P | AJ6: P | AK6: P | AL6: P | AM6: P | AN6: P | AQ6: P | AR6: P
B7: 1º | C7: JOSE AVERALDO LOPES | D7: SUPERVISOR SENIOR | F7: =COUNTIF(O7:AR7,$F$5) -> 20 | G7: =COUNTIF(O7:AR7,$G$5) -> 0 | H7: =COUNTIF(O7:AR7,$H$5) -> 0 | I7: =COUNTIF(O7:AR7,$I$5) -> 0 | J7: =COUNTIF(O7:AR7,$J$5) -> 0 | K7: =COUNTIF(O7:AR7,$K$5) -> 0 | L7: =COUNTIF(O7:AR7,$L$5) -> 0 | M7: =COUNTIF(O7:AR7,$M$5) -> 0 | O7: P | P7: P | Q7: P | V7: P | W7: P | X7: P | Y7: P | Z7: P | AC7: P | AD7: P | AE7: P | AF7: P | AG7: P | AJ7: P | AK7: P | AL7: P | AM7: P | AN7: P | AQ7: P | AR7: P
B8: 1º | C8: DOUGLAS MANOEL DA SILVA | D8: OPERADOR RETRATIL | F8: =COUNTIF(O8:AR8,$F$5) -> 20 | G8: =COUNTIF(O8:AR8,$G$5) -> 0 | H8: =COUNTIF(O8:AR8,$H$5) -> 0 | I8: =COUNTIF(O8:AR8,$I$5) -> 0 | J8: =COUNTIF(O8:AR8,$J$5) -> 0 | K8: =COUNTIF(O8:AR8,$K$5) -> 0 | L8: =COUNTIF(O8:AR8,$L$5) -> 0 | M8: =COUNTIF(O8:AR8,$M$5) -> 0 | O8: P | P8: P | Q8: P | V8: P | W8: P | X8: P | Y8: P | Z8: P | AC8: P | AD8: P | AE8: P | AF8: P | AG8: P | AJ8: P | AK8: P | AL8: P | AM8: P | AN8: P | AQ8: P | AR8: P
B9: 1º | C9: EDMILSON DOS SANTOS OLIVEIRA | D9: OPERADOR GLP | F9: =COUNTIF(O9:AR9,$F$5) -> 20 | G9: =COUNTIF(O9:AR9,$G$5) -> 0 | H9: =COUNTIF(O9:AR9,$H$5) -> 0 | I9: =COUNTIF(O9:AR9,$I$5) -> 0 | J9: =COUNTIF(O9:AR9,$J$5) -> 0 | K9: =COUNTIF(O9:AR9,$K$5) -> 0 | L9: =COUNTIF(O9:AR9,$L$5) -> 0 | M9: =COUNTIF(O9:AR9,$M$5) -> 0 | O9: P | P9: P | Q9: P | V9: P | W9: P | X9: P | Y9: P | Z9: P | AC9: P | AD9: P | AE9: P | AF9: P | AG9: P | AJ9: P | AK9: P | AL9: P | AM9: P | AN9: P | AQ9: P | AR9: P
B10: 1º | C10: EDSON NASCIMENTO DE ALMEIDA | D10: OPERADOR RETRATIL | F10: =COUNTIF(O10:AR10,$F$5) -> 20 | G10: =COUNTIF(O10:AR10,$G$5) -> 0 | H10: =COUNTIF(O10:AR10,$H$5) -> 0 | I10: =COUNTIF(O10:AR10,$I$5) -> 0 | J10: =COUNTIF(O10:AR10,$J$5) -> 0 | K10: =COUNTIF(O10:AR10,$K$5) -> 0 | L10: =COUNTIF(O10:AR10,$L$5) -> 0 | M10: =COUNTIF(O10:AR10,$M$5) -> 0 | O10: P | P10: P | Q10: P | V10: P | W10: P | X10: P | Y10: P | Z10: P | AC10: P | AD10: P | AE10: P | AF10: P | AG10: P | AJ10: P | AK10: P | AL10: P | AM10: P | AN10: P | AQ10: P | AR10: P
B11: 1º | C11: EDUARDO MORENO DOS SANTOS | D11: AJUDANTE LOGISTICO | F11: =COUNTIF(O11:AR11,$F$5) -> 20 | G11: =COUNTIF(O11:AR11,$G$5) -> 0 | H11: =COUNTIF(O11:AR11,$H$5) -> 0 | I11: =COUNTIF(O11:AR11,$I$5) -> 0 | J11: =COUNTIF(O11:AR11,$J$5) -> 0 | K11: =COUNTIF(O11:AR11,$K$5) -> 0 | L11: =COUNTIF(O11:AR11,$L$5) -> 0 | M11: =COUNTIF(O11:AR11,$M$5) -> 0 | O11: P | P11: P | Q11: P | V11: P | W11: P | X11: P | Y11: P | Z11: P | AC11: P | AD11: P | AE11: P | AF11: P | AG11: P | AJ11: P | AK11: P | AL11: P | AM11: P | AN11: P | AQ11: P | AR11: P
B12: 1º | C12: EMERSON CONCEIÇÃO DE AS | D12: OPERADOR RETRATIL | F12: =COUNTIF(O12:AR12,$F$5) -> 20 | G12: =COUNTIF(O12:AR12,$G$5) -> 0 | H12: =COUNTIF(O12:AR12,$H$5) -> 0 | I12: =COUNTIF(O12:AR12,$I$5) -> 0 | J12: =COUNTIF(O12:AR12,$J$5) -> 0 | K12: =COUNTIF(O12:AR12,$K$5) -> 0 | L12: =COUNTIF(O12:AR12,$L$5) -> 0 | M12: =COUNTIF(O12:AR12,$M$5) -> 0 | O12: P | P12: P | Q12: P | V12: P | W12: P | X12: P | Y12: P | Z12: P | AC12: P | AD12: P | AE12: P | AF12: P | AG12: P | AJ12: P | AK12: P | AL12: P | AM12: P | AN12: P | AQ12: P | AR12: P
B13: 1º | C13: EVERTON LOPES FERREIRA | D13: OP. SELECIONADORA | F13: =COUNTIF(O13:AR13,$F$5) -> 19 | G13: =COUNTIF(O13:AR13,$G$5) -> 0 | H13: =COUNTIF(O13:AR13,$H$5) -> 0 | I13: =COUNTIF(O13:AR13,$I$5) -> 1 | J13: =COUNTIF(O13:AR13,$J$5) -> 0 | K13: =COUNTIF(O13:AR13,$K$5) -> 0 | L13: =COUNTIF(O13:AR13,$L$5) -> 0 | M13: =COUNTIF(O13:AR13,$M$5) -> 0 | O13: P | P13: P | Q13: P | V13: P | W13: P | X13: P | Y13: P | Z13: P | AC13: P | AD13: P | AE13: P | AF13: FJ | AG13: P | AJ13: P | AK13: P | AL13: P | AM13: P | AN13: P | AQ13: P | AR13: P
B14: 1º | C14: FÁBIO FRANCISCO DA SILVA | D14: CONFERENTE | F14: =COUNTIF(O14:AR14,$F$5) -> 20 | G14: =COUNTIF(O14:AR14,$G$5) -> 0 | H14: =COUNTIF(O14:AR14,$H$5) -> 0 | I14: =COUNTIF(O14:AR14,$I$5) -> 0 | J14: =COUNTIF(O14:AR14,$J$5) -> 0 | K14: =COUNTIF(O14:AR14,$K$5) -> 0 | L14: =COUNTIF(O14:AR14,$L$5) -> 0 | M14: =COUNTIF(O14:AR14,$M$5) -> 0 | O14: P | P14: P | Q14: P | V14: P | W14: P | X14: P | Y14: P | Z14: P | AC14: P | AD14: P | AE14: P | AF14: P | AG14: P | AJ14: P | AK14: P | AL14: P | AM14: P | AN14: P | AQ14: P | AR14: P
B15: 1º | C15: FABRICIO OLIVEIRA DO AMARAL | D15: SUPERVISOR | F15: =COUNTIF(O15:AR15,$F$5) -> 20 | G15: =COUNTIF(O15:AR15,$G$5) -> 0 | H15: =COUNTIF(O15:AR15,$H$5) -> 0 | I15: =COUNTIF(O15:AR15,$I$5) -> 0 | J15: =COUNTIF(O15:AR15,$J$5) -> 0 | K15: =COUNTIF(O15:AR15,$K$5) -> 0 | L15: =COUNTIF(O15:AR15,$L$5) -> 0 | M15: =COUNTIF(O15:AR15,$M$5) -> 0 | O15: P | P15: P | Q15: P | V15: P | W15: P | X15: P | Y15: P | Z15: P | AC15: P | AD15: P | AE15: P | AF15: P | AG15: P | AJ15: P | AK15: P | AL15: P | AM15: P | AN15: P | AQ15: P | AR15: P
B16: 1º | C16: FERNANDO DE BRITTO GRABALOS | D16: OPERADOR RETRATIL | F16: =COUNTIF(O16:AR16,$F$5) -> 20 | G16: =COUNTIF(O16:AR16,$G$5) -> 0 | H16: =COUNTIF(O16:AR16,$H$5) -> 0 | I16: =COUNTIF(O16:AR16,$I$5) -> 0 | J16: =COUNTIF(O16:AR16,$J$5) -> 0 | K16: =COUNTIF(O16:AR16,$K$5) -> 0 | L16: =COUNTIF(O16:AR16,$L$5) -> 0 | M16: =COUNTIF(O16:AR16,$M$5) -> 0 | O16: P | P16: P | Q16: P | V16: P | W16: P | X16: P | Y16: P | Z16: P | AC16: P | AD16: P | AE16: P | AF16: P | AG16: P | AJ16: P | AK16: P | AL16: P | AM16: P | AN16: P | AQ16: P | AR16: P
B17: 1º | C17: GIUSEPPE CARDINALI JUNIOR | D17: OPERADOR RETRATIL | F17: =COUNTIF(O17:AR17,$F$5) -> 20 | G17: =COUNTIF(O17:AR17,$G$5) -> 0 | H17: =COUNTIF(O17:AR17,$H$5) -> 0 | I17: =COUNTIF(O17:AR17,$I$5) -> 0 | J17: =COUNTIF(O17:AR17,$J$5) -> 0 | K17: =COUNTIF(O17:AR17,$K$5) -> 0 | L17: =COUNTIF(O17:AR17,$L$5) -> 0 | M17: =COUNTIF(O17:AR17,$M$5) -> 0 | O17: P | P17: P | Q17: P | V17: P | W17: P | X17: P | Y17: P | Z17: P | AC17: P | AD17: P | AE17: P | AF17: P | AG17: P | AJ17: P | AK17: P | AL17: P | AM17: P | AN17: P | AQ17: P | AR17: P
... B46: 1º | C46: THIAGO SILVA SANTOS AMORIM | D46: CONFERENTE | F46: =COUNTIF(O46:AR46,$F$5) -> 20 | G46: =COUNTIF(O46:AR46,$G$5) -> 0 | H46: =COUNTIF(O46:AR46,$H$5) -> 0 | I46: =COUNTIF(O46:AR46,$I$5) -> 0 | J46: =COUNTIF(O46:AR46,$J$5) -> 0 | K46: =COUNTIF(O46:AR46,$K$5) -> 0 | L46: =COUNTIF(O46:AR46,$L$5) -> 0 | M46: =COUNTIF(O46:AR46,$M$5) -> 0 | O46: P | P46: P | Q46: P | V46: P | W46: P | X46: P | Y46: P | Z46: P | AC46: P | AD46: P | AE46: P | AF46: P | AG46: P | AJ46: P | AK46: P | AL46: P | AM46: P | AN46: P | AQ46: P | AR46: P
B47: 1º | C47: ADAILTON ALVES BORGES | D47: AJUDANTE LOGISTICO | F47: =COUNTIF(O47:AR47,$F$5) -> 7 | G47: =COUNTIF(O47:AR47,$G$5) -> 0 | H47: =COUNTIF(O47:AR47,$H$5) -> 0 | I47: =COUNTIF(O47:AR47,$I$5) -> 0 | J47: =COUNTIF(O47:AR47,$J$5) -> 0 | K47: =COUNTIF(O47:AR47,$K$5) -> 0 | L47: =COUNTIF(O47:AR47,$L$5) -> 0 | M47: =COUNTIF(O47:AR47,$M$5) -> 0 | Q47: P | V47: P | W47: P | X47: P | Y47: P | Z47: P | AC47: P
B48: 1º | C48: VICTOR DE LIMA DA SILVA | D48: AJUDANTE LOGISTICO | F48: =COUNTIF(O48:AR48,$F$5) -> 20 | G48: =COUNTIF(O48:AR48,$G$5) -> 0 | H48: =COUNTIF(O48:AR48,$H$5) -> 0 | I48: =COUNTIF(O48:AR48,$I$5) -> 0 | J48: =COUNTIF(O48:AR48,$J$5) -> 0 | K48: =COUNTIF(O48:AR48,$K$5) -> 0 | L48: =COUNTIF(O48:AR48,$L$5) -> 0 | M48: =COUNTIF(O48:AR48,$M$5) -> 0 | O48: P | P48: P | Q48: P | V48: P | W48: P | X48: P | Y48: P | Z48: P | AC48: P | AD48: P | AE48: P | AF48: P | AG48: P | AJ48: P | AK48: P | AL48: P | AM48: P | AN48: P | AQ48: P | AR48: P
B49: 1º | C49: VINICIUS MARCHI PANSICA | D49: AJUDANTE LOGISTICO | F49: =COUNTIF(O49:AR49,$F$5) -> 19 | G49: =COUNTIF(O49:AR49,$G$5) -> 0 | H49: =COUNTIF(O49:AR49,$H$5) -> 0 | I49: =COUNTIF(O49:AR49,$I$5) -> 1 | J49: =COUNTIF(O49:AR49,$J$5) -> 0 | K49: =COUNTIF(O49:AR49,$K$5) -> 0 | L49: =COUNTIF(O49:AR49,$L$5) -> 0 | M49: =COUNTIF(O49:AR49,$M$5) -> 0 | O49: P | P49: FJ | Q49: P | V49: P | W49: P | X49: P | Y49: P | Z49: P | AC49: P | AD49: P | AE49: P | AF49: P | AG49: P | AJ49: P | AK49: P | AL49: P | AM49: P | AN49: P | AQ49: P | AR49: P
B50: 1º | C50: JULIO APARECIDO DE LIMA SANTOS | D50: OP. SELECIONADORA | F50: =COUNTIF(O50:AR50,$F$5) -> 20 | G50: =COUNTIF(O50:AR50,$G$5) -> 0 | H50: =COUNTIF(O50:AR50,$H$5) -> 0 | I50: =COUNTIF(O50:AR50,$I$5) -> 0 | J50: =COUNTIF(O50:AR50,$J$5) -> 0 | K50: =COUNTIF(O50:AR50,$K$5) -> 0 | L50: =COUNTIF(O50:AR50,$L$5) -> 0 | M50: =COUNTIF(O50:AR50,$M$5) -> 0 | O50: P | P50: P | Q50: P | V50: P | W50: P | X50: P | Y50: P | Z50: P | AC50: P | AD50: P | AE50: P | AF50: P | AG50: P | AJ50: P | AK50: P | AL50: P | AM50: P | AN50: P | AQ50: P | AR50: P
B51: 1º | C51: CRISTIANO DA SILA | D51: OP. SELECIONADORA | F51: =COUNTIF(O51:AR51,$F$5) -> 19 | G51: =COUNTIF(O51:AR51,$G$5) -> 0 | H51: =COUNTIF(O51:AR51,$H$5) -> 0 | I51: =COUNTIF(O51:AR51,$I$5) -> 1 | J51: =COUNTIF(O51:AR51,$J$5) -> 0 | K51: =COUNTIF(O51:AR51,$K$5) -> 0 | L51: =COUNTIF(O51:AR51,$L$5) -> 0 | M51: =COUNTIF(O51:AR51,$M$5) -> 0 | O51: P | P51: P | Q51: P | V51: P | W51: P | X51: P | Y51: P | Z51: P | AC51: P | AD51: P | AE51: P | AF51: P | AG51: P | AJ51: P | AK51: P | AL51: P | AM51: P | AN51: FJ | AQ51: P | AR51: P
B52: 1º | C52: KESLEY EDUARDO SETE CAMILO | D52: OP. SELECIONADORA | F52: =COUNTIF(O52:AR52,$F$5) -> 14 | G52: =COUNTIF(O52:AR52,$G$5) -> 0 | H52: =COUNTIF(O52:AR52,$H$5) -> 1 | I52: =COUNTIF(O52:AR52,$I$5) -> 3 | J52: =COUNTIF(O52:AR52,$J$5) -> 0 | K52: =COUNTIF(O52:AR52,$K$5) -> 0 | L52: =COUNTIF(O52:AR52,$L$5) -> 0 | M52: =COUNTIF(O52:AR52,$M$5) -> 0 | Q52: P | V52: P | W52: P | X52: P | Y52: P | Z52: P | AC52: P | AD52: P | AE52: P | AF52: P | AG52: FJ | AJ52: P | AK52: P | AL52: P | AM52: FJ | AN52: FJ | AQ52: P | AR52: FN
B53: 1º | C53: LEONARDO COUTINHO COSTA | D53: OP. SELECIONADORA | F53: =COUNTIF(O53:AR53,$F$5) -> 20 | G53: =COUNTIF(O53:AR53,$G$5) -> 0 | H53: =COUNTIF(O53:AR53,$H$5) -> 0 | I53: =COUNTIF(O53:AR53,$I$5) -> 0 | J53: =COUNTIF(O53:AR53,$J$5) -> 0 | K53: =COUNTIF(O53:AR53,$K$5) -> 0 | L53: =COUNTIF(O53:AR53,$L$5) -> 0 | M53: =COUNTIF(O53:AR53,$M$5) -> 0 | O53: P | P53: P | Q53: P | V53: P | W53: P | X53: P | Y53: P | Z53: P | AC53: P | AD53: P | AE53: P | AF53: P | AG53: P | AJ53: P | AK53: P | AL53: P | AM53: P | AN53: P | AQ53: P | AR53: P
B54: 1º | C54: RAFAEL FERREIRA DA SILVA | D54: OPERADOR RETRATIL | F54: =COUNTIF(O54:AR54,$F$5) -> 20 | G54: =COUNTIF(O54:AR54,$G$5) -> 0 | H54: =COUNTIF(O54:AR54,$H$5) -> 0 | I54: =COUNTIF(O54:AR54,$I$5) -> 0 | J54: =COUNTIF(O54:AR54,$J$5) -> 0 | K54: =COUNTIF(O54:AR54,$K$5) -> 0 | L54: =COUNTIF(O54:AR54,$L$5) -> 0 | M54: =COUNTIF(O54:AR54,$M$5) -> 0 | O54: P | P54: P | Q54: P | V54: P | W54: P | X54: P | Y54: P | Z54: P | AC54: P | AD54: P | AE54: P | AF54: P | AG54: P | AJ54: P | AK54: P | AL54: P | AM54: P | AN54: P | AQ54: P | AR54: P
B55: 1º | C55: JOÃO VITOR NUNES FERREIRA | D55: AJUDANTE LOGISTICO | F55: =COUNTIF(O55:AR55,$F$5) -> 18 | G55: =COUNTIF(O55:AR55,$G$5) -> 0 | H55: =COUNTIF(O55:AR55,$H$5) -> 0 | I55: =COUNTIF(O55:AR55,$I$5) -> 0 | J55: =COUNTIF(O55:AR55,$J$5) -> 0 | K55: =COUNTIF(O55:AR55,$K$5) -> 0 | L55: =COUNTIF(O55:AR55,$L$5) -> 0 | M55: =COUNTIF(O55:AR55,$M$5) -> 0 | Q55: P | V55: P | W55: P | X55: P | Y55: P | Z55: P | AC55: P | AD55: P | AE55: P | AF55: P | AG55: P | AJ55: P | AK55: P | AL55: P | AM55: P | AN55: P | AQ55: P | AR55: P
B56: 2º | C56: CARLOS EDUARDO NOGUEIRA | D56: AJUDANTE LOGISTICO | F56: =COUNTIF(O56:AR56,$F$5) -> 20 | G56: =COUNTIF(O56:AR56,$G$5) -> 0 | H56: =COUNTIF(O56:AR56,$H$5) -> 0 | I56: =COUNTIF(O56:AR56,$I$5) -> 0 | J56: =COUNTIF(O56:AR56,$J$5) -> 0 | K56: =COUNTIF(O56:AR56,$K$5) -> 0 | L56: =COUNTIF(O56:AR56,$L$5) -> 0 | M56: =COUNTIF(O56:AR56,$M$5) -> 0 | O56: P | P56: P | Q56: P | V56: P | W56: P | X56: P | Y56: P | Z56: P | AC56: P | AD56: P | AE56: P | AF56: P | AG56: P | AJ56: P | AK56: P | AL56: P | AM56: P | AN56: P | AQ56: P | AR56: P
B57: 2º | C57: GUSTAVO YURI AMEDURO TUDA | D57: AJUDANTE LOGISTICO | F57: =COUNTIF(O57:AR57,$F$5) -> 20 | G57: =COUNTIF(O57:AR57,$G$5) -> 0 | H57: =COUNTIF(O57:AR57,$H$5) -> 0 | I57: =COUNTIF(O57:AR57,$I$5) -> 0 | J57: =COUNTIF(O57:AR57,$J$5) -> 0 | K57: =COUNTIF(O57:AR57,$K$5) -> 0 | L57: =COUNTIF(O57:AR57,$L$5) -> 0 | M57: =COUNTIF(O57:AR57,$M$5) -> 0 | O57: P | P57: P | Q57: P | V57: P | W57: P | X57: P | Y57: P | Z57: P | AC57: P | AD57: P | AE57: P | AF57: P | AG57: P | AJ57: P | AK57: P | AL57: P | AM57: P | AN57: P | AQ57: P | AR57: P
B58: 2º | C58: HIAGO FAGUNDES DE LIMA | D58: AJUDANTE LOGISTICO | F58: =COUNTIF(O58:AR58,$F$5) -> 13 | G58: =COUNTIF(O58:AR58,$G$5) -> 0 | H58: =COUNTIF(O58:AR58,$H$5) -> 1 | I58: =COUNTIF(O58:AR58,$I$5) -> 0 | J58: =COUNTIF(O58:AR58,$J$5) -> 0 | K58: =COUNTIF(O58:AR58,$K$5) -> 0 | L58: =COUNTIF(O58:AR58,$L$5) -> 0 | M58: =COUNTIF(O58:AR58,$M$5) -> 0 | Y58: P | Z58: P | AC58: P | AD58: P | AE58: P | AF58: P | AG58: P | AJ58: P | AK58: P | AL58: P | AM58: FN | AN58: P | AQ58: P | AR58: P
B59: 2º | C59: JAELSON AMORIM PEREIRA | D59: AJUDANTE LOGISTICO | F59: =COUNTIF(O59:AR59,$F$5) -> 20 | G59: =COUNTIF(O59:AR59,$G$5) -> 0 | H59: =COUNTIF(O59:AR59,$H$5) -> 0 | I59: =COUNTIF(O59:AR59,$I$5) -> 0 | J59: =COUNTIF(O59:AR59,$J$5) -> 0 | K59: =COUNTIF(O59:AR59,$K$5) -> 0 | L59: =COUNTIF(O59:AR59,$L$5) -> 0 | M59: =COUNTIF(O59:AR59,$M$5) -> 0 | O59: P | P59: P | Q59: P | V59: P | W59: P | X59: P | Y59: P | Z59: P | AC59: P | AD59: P | AE59: P | AF59: P | AG59: P | AJ59: P | AK59: P | AL59: P | AM59: P | AN59: P | AQ59: P | AR59: P
B60: 2º | C60: ROBERTO DE ARAUJO SANTOS | D60: AJUDANTE LOGISTICO | F60: =COUNTIF(O60:AR60,$F$5) -> 20 | G60: =COUNTIF(O60:AR60,$G$5) -> 0 | H60: =COUNTIF(O60:AR60,$H$5) -> 0 | I60: =COUNTIF(O60:AR60,$I$5) -> 0 | J60: =COUNTIF(O60:AR60,$J$5) -> 0 | K60: =COUNTIF(O60:AR60,$K$5) -> 0 | L60: =COUNTIF(O60:AR60,$L$5) -> 0 | M60: =COUNTIF(O60:AR60,$M$5) -> 0 | O60: P | P60: P | Q60: P | V60: P | W60: P | X60: P | Y60: P | Z60: P | AC60: P | AD60: P | AE60: P | AF60: P | AG60: P | AJ60: P | AK60: P | AL60: P | AM60: P | AN60: P | AQ60: P | AR60: P
B61: 2º | C61: RUAN ALVES DOS SANTOS | D61: AJUDANTE LOGISTICO | F61: =COUNTIF(O61:AR61,$F$5) -> 19 | G61: =COUNTIF(O61:AR61,$G$5) -> 0 | H61: =COUNTIF(O61:AR61,$H$5) -> 0 | I61: =COUNTIF(O61:AR61,$I$5) -> 1 | J61: =COUNTIF(O61:AR61,$J$5) -> 0 | K61: =COUNTIF(O61:AR61,$K$5) -> 0 | L61: =COUNTIF(O61:AR61,$L$5) -> 0 | M61: =COUNTIF(O61:AR61,$M$5) -> 0 | O61: P | P61: P | Q61: P | V61: FJ | W61: P | X61: P | Y61: P | Z61: P | AC61: P | AD61: P | AE61: P | AF61: P | AG61: P | AJ61: P | AK61: P | AL61: P | AM61: P | AN61: P | AQ61: P | AR61: P
B62: 2º | C62: SULAMITA DA PAZ FONSECA SOUSA | D62: AJUDANTE LOGISTICO | F62: =COUNTIF(O62:AR62,$F$5) -> 16 | G62: =COUNTIF(O62:AR62,$G$5) -> 0 | H62: =COUNTIF(O62:AR62,$H$5) -> 0 | I62: =COUNTIF(O62:AR62,$I$5) -> 4 | J62: =COUNTIF(O62:AR62,$J$5) -> 0 | K62: =COUNTIF(O62:AR62,$K$5) -> 0 | L62: =COUNTIF(O62:AR62,$L$5) -> 0 | M62: =COUNTIF(O62:AR62,$M$5) -> 0 | O62: P | P62: P | Q62: P | V62: FJ | W62: FJ | X62: P | Y62: P | Z62: P | AC62: P | AD62: P | AE62: P | AF62: P | AG62: P | AJ62: P | AK62: P | AL62: P | AM62: FJ | AN62: FJ | AQ62: P | AR62: P
B63: 2º | C63: KELVIN APARECIDO MARTINS TIMOTEO | D63: ANALISTA ADM | F63: =COUNTIF(O63:AR63,$F$5) -> 18 | G63: =COUNTIF(O63:AR63,$G$5) -> 0 | H63: =COUNTIF(O63:AR63,$H$5) -> 0 | I63: =COUNTIF(O63:AR63,$I$5) -> 2 | J63: =COUNTIF(O63:AR63,$J$5) -> 0 | K63: =COUNTIF(O63:AR63,$K$5) -> 0 | L63: =COUNTIF(O63:AR63,$L$5) -> 0 | M63: =COUNTIF(O63:AR63,$M$5) -> 0 | O63: P | P63: P | Q63: P | V63: P | W63: P | X63: P | Y63: P | Z63: P | AC63: P | AD63: P | AE63: P | AF63: P | AG63: P | AJ63: P | AK63: P | AL63: P | AM63: FJ | AN63: FJ | AQ63: P | AR63: P
B64: 2º | C64: ANDERSON BATISTA | D64: CONFERENTE | F64: =COUNTIF(O64:AR64,$F$5) -> 18 | G64: =COUNTIF(O64:AR64,$G$5) -> 0 | H64: =COUNTIF(O64:AR64,$H$5) -> 0 | I64: =COUNTIF(O64:AR64,$I$5) -> 1 | J64: =COUNTIF(O64:AR64,$J$5) -> 0 | K64: =COUNTIF(O64:AR64,$K$5) -> 0 | L64: =COUNTIF(O64:AR64,$L$5) -> 1 | M64: =COUNTIF(O64:AR64,$M$5) -> 0 | O64: P | P64: P | Q64: P | V64: P | W64: P | X64: P | Y64: P | Z64: P | AC64: P | AD64: S | AE64: FJ | AF64: P | AG64: P | AJ64: P | AK64: P | AL64: P | AM64: P | AN64: P | AQ64: P | AR64: P
B65: 2º | C65: BIANCA ANUCENA DE SOUSA | D65: CONFERENTE | F65: =COUNTIF(O65:AR65,$F$5) -> 18 | G65: =COUNTIF(O65:AR65,$G$5) -> 0 | H65: =COUNTIF(O65:AR65,$H$5) -> 0 | I65: =COUNTIF(O65:AR65,$I$5) -> 2 | J65: =COUNTIF(O65:AR65,$J$5) -> 0 | K65: =COUNTIF(O65:AR65,$K$5) -> 0 | L65: =COUNTIF(O65:AR65,$L$5) -> 0 | M65: =COUNTIF(O65:AR65,$M$5) -> 0 | O65: P | P65: P | Q65: P | V65: P | W65: P | X65: P | Y65: P | Z65: P | AC65: FJ | AD65: P | AE65: P | AF65: P | AG65: P | AJ65: P | AK65: P | AL65: P | AM65: FJ | AN65: P | AQ65: P | AR65: P
B66: 2º | C66: GABRIEL LUIS VIEIRA | D66: CONFERENTE | F66: =COUNTIF(O66:AR66,$F$5) -> 17 | G66: =COUNTIF(O66:AR66,$G$5) -> 0 | H66: =COUNTIF(O66:AR66,$H$5) -> 0 | I66: =COUNTIF(O66:AR66,$I$5) -> 0 | J66: =COUNTIF(O66:AR66,$J$5) -> 0 | K66: =COUNTIF(O66:AR66,$K$5) -> 0 | L66: =COUNTIF(O66:AR66,$L$5) -> 0 | M66: =COUNTIF(O66:AR66,$M$5) -> 0 | O66: P | P66: P | Q66: P | V66: P | W66: P | X66: P | Y66: P | Z66: P | AC66: P | AD66: P | AE66: P | AF66: P | AG66: P | AM66: P | AN66: P | AQ66: P | AR66: P
B67: 2º | C67: PAOLO JUSTINO MOREIRA | D67: CONFERENTE | F67: =COUNTIF(O67:AR67,$F$5) -> 20 | G67: =COUNTIF(O67:AR67,$G$5) -> 0 | H67: =COUNTIF(O67:AR67,$H$5) -> 0 | I67: =COUNTIF(O67:AR67,$I$5) -> 0 | J67: =COUNTIF(O67:AR67,$J$5) -> 0 | K67: =COUNTIF(O67:AR67,$K$5) -> 0 | L67: =COUNTIF(O67:AR67,$L$5) -> 0 | M67: =COUNTIF(O67:AR67,$M$5) -> 0 | O67: P | P67: P | Q67: P | V67: P | W67: P | X67: P | Y67: P | Z67: P | AC67: P | AD67: P | AE67: P | AF67: P | AG67: P | AJ67: P | AK67: P | AL67: P | AM67: P | AN67: P | AQ67: P | AR67: P
B68: 2º | C68: CICERO ELAN | D68: LIDER | F68: =COUNTIF(O68:AR68,$F$5) -> 20 | G68: =COUNTIF(O68:AR68,$G$5) -> 0 | H68: =COUNTIF(O68:AR68,$H$5) -> 0 | I68: =COUNTIF(O68:AR68,$I$5) -> 0 | J68: =COUNTIF(O68:AR68,$J$5) -> 0 | K68: =COUNTIF(O68:AR68,$K$5) -> 0 | L68: =COUNTIF(O68:AR68,$L$5) -> 0 | M68: =COUNTIF(O68:AR68,$M$5) -> 0 | O68: P | P68: P | Q68: P | V68: P | W68: P | X68: P | Y68: P | Z68: P | AC68: P | AD68: P | AE68: P | AF68: P | AG68: P | AJ68: P | AK68: P | AL68: P | AM68: P | AN68: P | AQ68: P | AR68: P
B69: 2º | C69: MARCOS PRADO | D69: LIDER | F69: =COUNTIF(O69:AR69,$F$5) -> 20 | G69: =COUNTIF(O69:AR69,$G$5) -> 0 | H69: =COUNTIF(O69:AR69,$H$5) -> 0 | I69: =COUNTIF(O69:AR69,$I$5) -> 0 | J69: =COUNTIF(O69:AR69,$J$5) -> 0 | K69: =COUNTIF(O69:AR69,$K$5) -> 0 | L69: =COUNTIF(O69:AR69,$L$5) -> 0 | M69: =COUNTIF(O69:AR69,$M$5) -> 0 | O69: P | P69: P | Q69: P | V69: P | W69: P | X69: P | Y69: P | Z69: P | AC69: P | AD69: P | AE69: P | AF69: P | AG69: P | AJ69: P | AK69: P | AL69: P | AM69: P | AN69: P | AQ69: P | AR69: P
B70: 2º | C70: BRUNO HENRIQUE | D70: OP. SELECIONADORA | F70: =COUNTIF(O70:AR70,$F$5) -> 0 | G70: =COUNTIF(O70:AR70,$G$5) -> 0 | H70: =COUNTIF(O70:AR70,$H$5) -> 0 | I70: =COUNTIF(O70:AR70,$I$5) -> 0 | J70: =COUNTIF(O70:AR70,$J$5) -> 20 | K70: =COUNTIF(O70:AR70,$K$5) -> 0 | L70: =COUNTIF(O70:AR70,$L$5) -> 0 | M70: =COUNTIF(O70:AR70,$M$5) -> 0 | O70: A | P70: A | Q70: A | V70: A | W70: A | X70: A | Y70: A | Z70: A | AC70: A | AD70: A | AE70: A | AF70: A | AG70: A | AJ70: A | AK70: A | AL70: A | AM70: A | AN70: A | AQ70: A | AR70: A
...

Sheet JULHO
B2: ABSENTEÍSMO EXPEDIÇÃO - JULHO 2026
O4: QUA | P4: QUI | Q4: SEX | R4: SÁB | S4: DOM | T4: SEG | U4: TER | V4: QUA | W4: QUI | X4: SEX | Y4: SÁB | Z4: DOM | AA4: SEG | AB4: TER | AC4: QUA | AD4: QUI | AE4: SEX | AF4: SÁB | AG4: DOM | AH4: SEG | AI4: TER | AJ4: QUA | AK4: QUI | AL4: SEX | AM4: SÁB | AN4: DOM | AO4: SEG | AP4: TER | AQ4: QUA | AR4: QUI | AS4: SEX
B5: TURNO | C5: NOME COMPLETO | D5: FUNÇÃO | F5: P | G5: BH | H5: FN | I5: FJ | J5: A | K5: T | L5: S | M5: F | O5: 46204 | P5: 46205 | Q5: 46206 | R5: 46207 | S5: 46208 | T5: 46209 | U5: 46210 | V5: 46211 | W5: 46212 | X5: 46213 | Y5: 46214 | Z5: 46215 | AA5: 46216 | AB5: 46217 | AC5: 46218 | AD5: 46219 | AE5: 46220 | AF5: 46221 | AG5: 46222 | AH5: 46223 | AI5: 46224 | AJ5: 46225 | AK5: 46226 | AL5: 46227 | AM5: 46228 | AN5: 46229 | AO5: 46230 | AP5: 46231 | AQ5: 46232 | AR5: 46233 | AS5: 46234
B6: 1º | C6: CICERO ROBERTO DA SILVA | D6: OPERADOR GLP | F6: =COUNTIF(O6:AS6,$F$5) -> 2 | G6: =COUNTIF(O6:AS6,$G$5) -> 0 | H6: =COUNTIF(O6:AS6,$H$5) -> 0 | I6: =COUNTIF(O6:AS6,$I$5) -> 0 | J6: =COUNTIF(O6:AS6,$J$5) -> 0 | K6: =COUNTIF(O6:AS6,$K$5) -> 0 | L6: =COUNTIF(O6:AS6,$L$5) -> 0 | M6: =COUNTIF(O6:AS6,$M$5) -> 0 | O6: P | P6: P
B7: 1º | C7: JOSE AVERALDO LOPES | D7: SUPERVISOR SENIOR | F7: =COUNTIF(O7:AS7,$F$5) -> 2 | G7: =COUNTIF(O7:AS7,$G$5) -> 0 | H7: =COUNTIF(O7:AS7,$H$5) -> 0 | I7: =COUNTIF(O7:AS7,$I$5) -> 0 | J7: =COUNTIF(O7:AS7,$J$5) -> 0 | K7: =COUNTIF(O7:AS7,$K$5) -> 0 | L7: =COUNTIF(O7:AS7,$L$5) -> 0 | M7: =COUNTIF(O7:AS7,$M$5) -> 0 | O7: P | P7: P
B8: 1º | C8: DOUGLAS MANOEL DA SILVA | D8: OPERADOR RETRATIL | F8: =COUNTIF(O8:AS8,$F$5) -> 2 | G8: =COUNTIF(O8:AS8,$G$5) -> 0 | H8: =COUNTIF(O8:AS8,$H$5) -> 0 | I8: =COUNTIF(O8:AS8,$I$5) -> 0 | J8: =COUNTIF(O8:AS8,$J$5) -> 0 | K8: =COUNTIF(O8:AS8,$K$5) -> 0 | L8: =COUNTIF(O8:AS8,$L$5) -> 0 | M8: =COUNTIF(O8:AS8,$M$5) -> 0 | O8: P | P8: P
B9: 1º | C9: EDMILSON DOS SANTOS OLIVEIRA | D9: OPERADOR GLP | F9: =COUNTIF(O9:AS9,$F$5) -> 2 | G9: =COUNTIF(O9:AS9,$G$5) -> 0 | H9: =COUNTIF(O9:AS9,$H$5) -> 0 | I9: =COUNTIF(O9:AS9,$I$5) -> 0 | J9: =COUNTIF(O9:AS9,$J$5) -> 0 | K9: =COUNTIF(O9:AS9,$K$5) -> 0 | L9: =COUNTIF(O9:AS9,$L$5) -> 0 | M9: =COUNTIF(O9:AS9,$M$5) -> 0 | O9: P | P9: P
B10: 1º | C10: EDSON NASCIMENTO DE ALMEIDA | D10: OPERADOR RETRATIL | F10: =COUNTIF(O10:AS10,$F$5) -> 2 | G10: =COUNTIF(O10:AS10,$G$5) -> 0 | H10: =COUNTIF(O10:AS10,$H$5) -> 0 | I10: =COUNTIF(O10:AS10,$I$5) -> 0 | J10: =COUNTIF(O10:AS10,$J$5) -> 0 | K10: =COUNTIF(O10:AS10,$K$5) -> 0 | L10: =COUNTIF(O10:AS10,$L$5) -> 0 | M10: =COUNTIF(O10:AS10,$M$5) -> 0 | O10: P | P10: P
B11: 1º | C11: EDUARDO MORENO DOS SANTOS | D11: AJUDANTE LOGISTICO | F11: =COUNTIF(O11:AS11,$F$5) -> 2 | G11: =COUNTIF(O11:AS11,$G$5) -> 0 | H11: =COUNTIF(O11:AS11,$H$5) -> 0 | I11: =COUNTIF(O11:AS11,$I$5) -> 0 | J11: =COUNTIF(O11:AS11,$J$5) -> 0 | K11: =COUNTIF(O11:AS11,$K$5) -> 0 | L11: =COUNTIF(O11:AS11,$L$5) -> 0 | M11: =COUNTIF(O11:AS11,$M$5) -> 0 | O11: P | P11: P
B12: 1º | C12: EMERSON CONCEIÇÃO DE AS | D12: OPERADOR RETRATIL | F12: =COUNTIF(O12:AS12,$F$5) -> 2 | G12: =COUNTIF(O12:AS12,$G$5) -> 0 | H12: =COUNTIF(O12:AS12,$H$5) -> 0 | I12: =COUNTIF(O12:AS12,$I$5) -> 0 | J12: =COUNTIF(O12:AS12,$J$5) -> 0 | K12: =COUNTIF(O12:AS12,$K$5) -> 0 | L12: =COUNTIF(O12:AS12,$L$5) -> 0 | M12: =COUNTIF(O12:AS12,$M$5) -> 0 | O12: P | P12: P
B13: 1º | C13: EVERTON LOPES FERREIRA | D13: OP. SELECIONADORA | F13: =COUNTIF(O13:AS13,$F$5) -> 2 | G13: =COUNTIF(O13:AS13,$G$5) -> 0 | H13: =COUNTIF(O13:AS13,$H$5) -> 0 | I13: =COUNTIF(O13:AS13,$I$5) -> 0 | J13: =COUNTIF(O13:AS13,$J$5) -> 0 | K13: =COUNTIF(O13:AS13,$K$5) -> 0 | L13: =COUNTIF(O13:AS13,$L$5) -> 0 | M13: =COUNTIF(O13:AS13,$M$5) -> 0 | O13: P | P13: P
B14: 1º | C14: FÁBIO FRANCISCO DA SILVA | D14: CONFERENTE | F14: =COUNTIF(O14:AS14,$F$5) -> 2 | G14: =COUNTIF(O14:AS14,$G$5) -> 0 | H14: =COUNTIF(O14:AS14,$H$5) -> 0 | I14: =COUNTIF(O14:AS14,$I$5) -> 0 | J14: =COUNTIF(O14:AS14,$J$5) -> 0 | K14: =COUNTIF(O14:AS14,$K$5) -> 0 | L14: =COUNTIF(O14:AS14,$L$5) -> 0 | M14: =COUNTIF(O14:AS14,$M$5) -> 0 | O14: P | P14: P
B15: 1º | C15: FABRICIO OLIVEIRA DO AMARAL | D15: SUPERVISOR | F15: =COUNTIF(O15:AS15,$F$5) -> 2 | G15: =COUNTIF(O15:AS15,$G$5) -> 0 | H15: =COUNTIF(O15:AS15,$H$5) -> 0 | I15: =COUNTIF(O15:AS15,$I$5) -> 0 | J15: =COUNTIF(O15:AS15,$J$5) -> 0 | K15: =COUNTIF(O15:AS15,$K$5) -> 0 | L15: =COUNTIF(O15:AS15,$L$5) -> 0 | M15: =COUNTIF(O15:AS15,$M$5) -> 0 | O15: P | P15: P
B16: 1º | C16: FERNANDO DE BRITTO GRABALOS | D16: OPERADOR RETRATIL | F16: =COUNTIF(O16:AS16,$F$5) -> 2 | G16: =COUNTIF(O16:AS16,$G$5) -> 0 | H16: =COUNTIF(O16:AS16,$H$5) -> 0 | I16: =COUNTIF(O16:AS16,$I$5) -> 0 | J16: =COUNTIF(O16:AS16,$J$5) -> 0 | K16: =COUNTIF(O16:AS16,$K$5) -> 0 | L16: =COUNTIF(O16:AS16,$L$5) -> 0 | M16: =COUNTIF(O16:AS16,$M$5) -> 0 | O16: P | P16: P
B17: 1º | C17: GIUSEPPE CARDINALI JUNIOR | D17: OPERADOR RETRATIL | F17: =COUNTIF(O17:AS17,$F$5) -> 2 | G17: =COUNTIF(O17:AS17,$G$5) -> 0 | H17: =COUNTIF(O17:AS17,$H$5) -> 0 | I17: =COUNTIF(O17:AS17,$I$5) -> 0 | J17: =COUNTIF(O17:AS17,$J$5) -> 0 | K17: =COUNTIF(O17:AS17,$K$5) -> 0 | L17: =COUNTIF(O17:AS17,$L$5) -> 0 | M17: =COUNTIF(O17:AS17,$M$5) -> 0 | O17: P | P17: P
... B46: 1º | C46: THIAGO SILVA SANTOS AMORIM | D46: CONFERENTE | F46: =COUNTIF(O46:AS46,$F$5) -> 2 | G46: =COUNTIF(O46:AS46,$G$5) -> 0 | H46: =COUNTIF(O46:AS46,$H$5) -> 0 | I46: =COUNTIF(O46:AS46,$I$5) -> 0 | J46: =COUNTIF(O46:AS46,$J$5) -> 0 | K46: =COUNTIF(O46:AS46,$K$5) -> 0 | L46: =COUNTIF(O46:AS46,$L$5) -> 0 | M46: =COUNTIF(O46:AS46,$M$5) -> 0 | O46: P | P46: P
B47: 1º | C47: REPOR VAGA | D47: AJUDANTE LOGISTICO | F47: =COUNTIF(O47:AS47,$F$5) -> 0 | G47: =COUNTIF(O47:AS47,$G$5) -> 0 | H47: =COUNTIF(O47:AS47,$H$5) -> 0 | I47: =COUNTIF(O47:AS47,$I$5) -> 0 | J47: =COUNTIF(O47:AS47,$J$5) -> 0 | K47: =COUNTIF(O47:AS47,$K$5) -> 0 | L47: =COUNTIF(O47:AS47,$L$5) -> 0 | M47: =COUNTIF(O47:AS47,$M$5) -> 0
B48: 1º | C48: VICTOR DE LIMA DA SILVA | D48: AJUDANTE LOGISTICO | F48: =COUNTIF(O48:AS48,$F$5) -> 2 | G48: =COUNTIF(O48:AS48,$G$5) -> 0 | H48: =COUNTIF(O48:AS48,$H$5) -> 0 | I48: =COUNTIF(O48:AS48,$I$5) -> 0 | J48: =COUNTIF(O48:AS48,$J$5) -> 0 | K48: =COUNTIF(O48:AS48,$K$5) -> 0 | L48: =COUNTIF(O48:AS48,$L$5) -> 0 | M48: =COUNTIF(O48:AS48,$M$5) -> 0 | O48: P | P48: P
B49: 1º | C49: VINICIUS MARCHI PANSICA | D49: AJUDANTE LOGISTICO | F49: =COUNTIF(O49:AS49,$F$5) -> 2 | G49: =COUNTIF(O49:AS49,$G$5) -> 0 | H49: =COUNTIF(O49:AS49,$H$5) -> 0 | I49: =COUNTIF(O49:AS49,$I$5) -> 0 | J49: =COUNTIF(O49:AS49,$J$5) -> 0 | K49: =COUNTIF(O49:AS49,$K$5) -> 0 | L49: =COUNTIF(O49:AS49,$L$5) -> 0 | M49: =COUNTIF(O49:AS49,$M$5) -> 0 | O49: P | P49: P
B50: 1º | C50: JULIO APARECIDO DE LIMA SANTOS | D50: OP. SELECIONADORA | F50: =COUNTIF(O50:AS50,$F$5) -> 2 | G50: =COUNTIF(O50:AS50,$G$5) -> 0 | H50: =COUNTIF(O50:AS50,$H$5) -> 0 | I50: =COUNTIF(O50:AS50,$I$5) -> 0 | J50: =COUNTIF(O50:AS50,$J$5) -> 0 | K50: =COUNTIF(O50:AS50,$K$5) -> 0 | L50: =COUNTIF(O50:AS50,$L$5) -> 0 | M50: =COUNTIF(O50:AS50,$M$5) -> 0 | O50: P | P50: P
B51: 1º | C51: CRISTIANO DA SILA | D51: OP. SELECIONADORA | F51: =COUNTIF(O51:AS51,$F$5) -> 2 | G51: =COUNTIF(O51:AS51,$G$5) -> 0 | H51: =COUNTIF(O51:AS51,$H$5) -> 0 | I51: =COUNTIF(O51:AS51,$I$5) -> 0 | J51: =COUNTIF(O51:AS51,$J$5) -> 0 | K51: =COUNTIF(O51:AS51,$K$5) -> 0 | L51: =COUNTIF(O51:AS51,$L$5) -> 0 | M51: =COUNTIF(O51:AS51,$M$5) -> 0 | O51: P | P51: P
B52: 1º | C52: KESLEY EDUARDO SETE CAMILO | D52: OP. SELECIONADORA | F52: =COUNTIF(O52:AS52,$F$5) -> 0 | G52: =COUNTIF(O52:AS52,$G$5) -> 0 | H52: =COUNTIF(O52:AS52,$H$5) -> 0 | I52: =COUNTIF(O52:AS52,$I$5) -> 2 | J52: =COUNTIF(O52:AS52,$J$5) -> 0 | K52: =COUNTIF(O52:AS52,$K$5) -> 0 | L52: =COUNTIF(O52:AS52,$L$5) -> 0 | M52: =COUNTIF(O52:AS52,$M$5) -> 0 | O52: FJ | P52: FJ
B53: 1º | C53: LEONARDO COUTINHO COSTA | D53: OP. SELECIONADORA | F53: =COUNTIF(O53:AS53,$F$5) -> 2 | G53: =COUNTIF(O53:AS53,$G$5) -> 0 | H53: =COUNTIF(O53:AS53,$H$5) -> 0 | I53: =COUNTIF(O53:AS53,$I$5) -> 0 | J53: =COUNTIF(O53:AS53,$J$5) -> 0 | K53: =COUNTIF(O53:AS53,$K$5) -> 0 | L53: =COUNTIF(O53:AS53,$L$5) -> 0 | M53: =COUNTIF(O53:AS53,$M$5) -> 0 | O53: P | P53: P
B54: 1º | C54: RAFAEL FERREIRA DA SILVA | D54: OPERADOR RETRATIL | F54: =COUNTIF(O54:AS54,$F$5) -> 2 | G54: =COUNTIF(O54:AS54,$G$5) -> 0 | H54: =COUNTIF(O54:AS54,$H$5) -> 0 | I54: =COUNTIF(O54:AS54,$I$5) -> 0 | J54: =COUNTIF(O54:AS54,$J$5) -> 0 | K54: =COUNTIF(O54:AS54,$K$5) -> 0 | L54: =COUNTIF(O54:AS54,$L$5) -> 0 | M54: =COUNTIF(O54:AS54,$M$5) -> 0 | O54: P | P54: P
B55: 1º | C55: JOÃO VITOR NUNES FERREIRA | D55: AJUDANTE LOGISTICO | F55: =COUNTIF(O55:AS55,$F$5) -> 2 | G55: =COUNTIF(O55:AS55,$G$5) -> 0 | H55: =COUNTIF(O55:AS55,$H$5) -> 0 | I55: =COUNTIF(O55:AS55,$I$5) -> 0 | J55: =COUNTIF(O55:AS55,$J$5) -> 0 | K55: =COUNTIF(O55:AS55,$K$5) -> 0 | L55: =COUNTIF(O55:AS55,$L$5) -> 0 | M55: =COUNTIF(O55:AS55,$M$5) -> 0 | O55: P | P55: P
B56: 2º | C56: CARLOS EDUARDO NOGUEIRA | D56: AJUDANTE LOGISTICO | F56: =COUNTIF(O56:AS56,$F$5) -> 2 | G56: =COUNTIF(O56:AS56,$G$5) -> 0 | H56: =COUNTIF(O56:AS56,$H$5) -> 0 | I56: =COUNTIF(O56:AS56,$I$5) -> 0 | J56: =COUNTIF(O56:AS56,$J$5) -> 0 | K56: =COUNTIF(O56:AS56,$K$5) -> 0 | L56: =COUNTIF(O56:AS56,$L$5) -> 0 | M56: =COUNTIF(O56:AS56,$M$5) -> 0 | O56: P | P56: P
B57: 2º | C57: GUSTAVO YURI AMEDURO TUDA | D57: AJUDANTE LOGISTICO | F57: =COUNTIF(O57:AS57,$F$5) -> 2 | G57: =COUNTIF(O57:AS57,$G$5) -> 0 | H57: =COUNTIF(O57:AS57,$H$5) -> 0 | I57: =COUNTIF(O57:AS57,$I$5) -> 0 | J57: =COUNTIF(O57:AS57,$J$5) -> 0 | K57: =COUNTIF(O57:AS57,$K$5) -> 0 | L57: =COUNTIF(O57:AS57,$L$5) -> 0 | M57: =COUNTIF(O57:AS57,$M$5) -> 0 | O57: P | P57: P
B58: 2º | C58: HIAGO FAGUNDES DE LIMA | D58: AJUDANTE LOGISTICO | F58: =COUNTIF(O58:AS58,$F$5) -> 2 | G58: =COUNTIF(O58:AS58,$G$5) -> 0 | H58: =COUNTIF(O58:AS58,$H$5) -> 0 | I58: =COUNTIF(O58:AS58,$I$5) -> 0 | J58: =COUNTIF(O58:AS58,$J$5) -> 0 | K58: =COUNTIF(O58:AS58,$K$5) -> 0 | L58: =COUNTIF(O58:AS58,$L$5) -> 0 | M58: =COUNTIF(O58:AS58,$M$5) -> 0 | O58: P | P58: P
B59: 2º | C59: JAELSON AMORIM PEREIRA | D59: AJUDANTE LOGISTICO | F59: =COUNTIF(O59:AS59,$F$5) -> 2 | G59: =COUNTIF(O59:AS59,$G$5) -> 0 | H59: =COUNTIF(O59:AS59,$H$5) -> 0 | I59: =COUNTIF(O59:AS59,$I$5) -> 0 | J59: =COUNTIF(O59:AS59,$J$5) -> 0 | K59: =COUNTIF(O59:AS59,$K$5) -> 0 | L59: =COUNTIF(O59:AS59,$L$5) -> 0 | M59: =COUNTIF(O59:AS59,$M$5) -> 0 | O59: P | P59: P
... B68: 2º | C68: MARCOS PRADO | D68: LIDER | F68: =COUNTIF(O68:AS68,$F$5) -> 2 | G68: =COUNTIF(O68:AS68,$G$5) -> 0 | H68: =COUNTIF(O68:AS68,$H$5) -> 0 | I68: =COUNTIF(O68:AS68,$I$5) -> 0 | J68: =COUNTIF(O68:AS68,$J$5) -> 0 | K68: =COUNTIF(O68:AS68,$K$5) -> 0 | L68: =COUNTIF(O68:AS68,$L$5) -> 0 | M68: =COUNTIF(O68:AS68,$M$5) -> 0 | O68: P | P68: P
B69: 2º | C69: BRUNO HENRIQUE | D69: OP. SELECIONADORA | F69: =COUNTIF(O69:AS69,$F$5) -> 0 | G69: =COUNTIF(O69:AS69,$G$5) -> 0 | H69: =COUNTIF(O69:AS69,$H$5) -> 0 | I69: =COUNTIF(O69:AS69,$I$5) -> 0 | J69: =COUNTIF(O69:AS69,$J$5) -> 3 | K69: =COUNTIF(O69:AS69,$K$5) -> 0 | L69: =COUNTIF(O69:AS69,$L$5) -> 0 | M69: =COUNTIF(O69:AS69,$M$5) -> 0 | O69: A | P69: A | Q69: A
B70: 1º | C70: GABRIEL SOARES GOMES | D70: CONFERENTE | F70: =COUNTIF(O70:AS70,$F$5) -> 2 | G70: =COUNTIF(O70:AS70,$G$5) -> 0 | H70: =COUNTIF(O70:AS70,$H$5) -> 0 | I70: =COUNTIF(O70:AS70,$I$5) -> 0 | J70: =COUNTIF(O70:AS70,$J$5) -> 0 | K70: =COUNTIF(O70:AS70,$K$5) -> 0 | L70: =COUNTIF(O70:AS70,$L$5) -> 0 | M70: =COUNTIF(O70:AS70,$M$5) -> 0 | O70: P | P70: P
B71: 2º | C71: GUILHERME DOS SANTOS MAGALHAES | D71: OP. SELECIONADORA | F71: =COUNTIF(O71:AS71,$F$5) -> 2 | G71: =COUNTIF(O71:AS71,$G$5) -> 0 | H71: =COUNTIF(O71:AS71,$H$5) -> 0 | I71: =COUNTIF(O71:AS71,$I$5) -> 0 | J71: =COUNTIF(O71:AS71,$J$5) -> 0 | K71: =COUNTIF(O71:AS71,$K$5) -> 0 | L71: =COUNTIF(O71:AS71,$L$5) -> 0 | M71: =COUNTIF(O71:AS71,$M$5) -> 0 | O71: P | P71: P
B72: 2º | C72: IGOR SANTANA DA SILVA | D72: OP. SELECIONADORA | F72: =COUNTIF(O72:AS72,$F$5) -> 2 | G72: =COUNTIF(O72:AS72,$G$5) -> 0 | H72: =COUNTIF(O72:AS72,$H$5) -> 0 | I72: =COUNTIF(O72:AS72,$I$5) -> 0 | J72: =COUNTIF(O72:AS72,$J$5) -> 0 | K72: =COUNTIF(O72:AS72,$K$5) -> 0 | L72: =COUNTIF(O72:AS72,$L$5) -> 0 | M72: =COUNTIF(O72:AS72,$M$5) -> 0 | O72: P | P72: P
B73: 2º | C73: JOÃO GABRIEL DANIEL DO NASCIMENTO | D73: OP. SELECIONADORA | F73: =COUNTIF(O73:AS73,$F$5) -> 1 | G73: =COUNTIF(O73:AS73,$G$5) -> 0 | H73: =COUNTIF(O73:AS73,$H$5) -> 0 | I73: =COUNTIF(O73:AS73,$I$5) -> 1 | J73: =COUNTIF(O73:AS73,$J$5) -> 0 | K73: =COUNTIF(O73:AS73,$K$5) -> 0 | L73: =COUNTIF(O73:AS73,$L$5) -> 0 | M73: =COUNTIF(O73:AS73,$M$5) -> 0 | O73: P | P73: FJ
B74: 2º | C74: NICHOLAS CANDIDO GALDINO | D74: OP. SELECIONADORA | F74: =COUNTIF(O74:AS74,$F$5) -> 2 | G74: =COUNTIF(O74:AS74,$G$5) -> 0 | H74: =COUNTIF(O74:AS74,$H$5) -> 0 | I74: =COUNTIF(O74:AS74,$I$5) -> 0 | J74: =COUNTIF(O74:AS74,$J$5) -> 0 | K74: =COUNTIF(O74:AS74,$K$5) -> 0 | L74: =COUNTIF(O74:AS74,$L$5) -> 0 | M74: =COUNTIF(O74:AS74,$M$5) -> 0 | O74: P | P74: P
B75: 2º | C75: RAILDA ALVES DE OLIVEIRA | D75: OP. SELECIONADORA | F75: =COUNTIF(O75:AS75,$F$5) -> 1 | G75: =COUNTIF(O75:AS75,$G$5) -> 0 | H75: =COUNTIF(O75:AS75,$H$5) -> 0 | I75: =COUNTIF(O75:AS75,$I$5) -> 0 | J75: =COUNTIF(O75:AS75,$J$5) -> 0 | K75: =COUNTIF(O75:AS75,$K$5) -> 0 | L75: =COUNTIF(O75:AS75,$L$5) -> 1 | M75: =COUNTIF(O75:AS75,$M$5) -> 0 | O75: S | P75: P
B76: 2º | C76: ANDRE CONSTANTINO DA SILVA | D76: OPERADOR GLP | F76: =COUNTIF(O76:AS76,$F$5) -> 2 | G76: =COUNTIF(O76:AS76,$G$5) -> 0 | H76: =COUNTIF(O76:AS76,$H$5) -> 0 | I76: =COUNTIF(O76:AS76,$I$5) -> 0 | J76: =COUNTIF(O76:AS76,$J$5) -> 0 | K76: =COUNTIF(O76:AS76,$K$5) -> 0 | L76: =COUNTIF(O76:AS76,$L$5) -> 0 | M76: =COUNTIF(O76:AS76,$M$5) -> 0 | O76: P | P76: P
B77: 2º | C77: CARLOS ALBERTO DA SILVA | D77: OPERADOR GLP | F77: =COUNTIF(O77:AS77,$F$5) -> 2 | G77: =COUNTIF(O77:AS77,$G$5) -> 0 | H77: =COUNTIF(O77:AS77,$H$5) -> 0 | I77: =COUNTIF(O77:AS77,$I$5) -> 0 | J77: =COUNTIF(O77:AS77,$J$5) -> 0 | K77: =COUNTIF(O77:AS77,$K$5) -> 0 | L77: =COUNTIF(O77:AS77,$L$5) -> 0 | M77: =COUNTIF(O77:AS77,$M$5) -> 0 | O77: P | P77: P
B78: 2º | C78: EDMAR NUNES | D78: OPERADOR GLP | F78: =COUNTIF(O78:AS78,$F$5) -> 2 | G78: =COUNTIF(O78:AS78,$G$5) -> 0 | H78: =COUNTIF(O78:AS78,$H$5) -> 0 | I78: =COUNTIF(O78:AS78,$I$5) -> 0 | J78: =COUNTIF(O78:AS78,$J$5) -> 0 | K78: =COUNTIF(O78:AS78,$K$5) -> 0 | L78: =COUNTIF(O78:AS78,$L$5) -> 0 | M78: =COUNTIF(O78:AS78,$M$5) -> 0 | O78: P | P78: P
...
